<mujoco>
  <body name="femur_l" pos="-0.056276 -0.07849 -0.07726" quat="1.0 0.0 0.0 0.0">

    <geom name="l_femur" type="mesh" mesh="l_femur" class="bone" />
    <geom name="femur_skin_l" size="0.067" class="skin" fromto="0 -0.05 -0.01 0 -0.39 0" />

    <inertial pos="       0    -0.17        0" mass="9.3014" fullinertia="  0.1339   0.0351   0.1412        0        0        0" />
    <geom name="PECT_at_femshaft_l" pos=" 0.00608573 -0.0845029 -0.0304405" euler=" -1.81295 -0.276344 0" class="wrap" size="0.015 0.025" type="cylinder" />
    <geom name="AMisch_at_condyles_l" pos=" -0.0226511 -0.376831 0.00315437" euler=" -1.71115 0.463363 0" class="wrap" size="0.04 0.12" type="cylinder" />
    <site name="addmagIsch_l_AMisch_at_condyles_l_sidesite" pos="-0.02265 -0.37683 0.05315" />
    <geom name="AMdist_at_femshaft_l" pos=" 0.0316065 -0.260736 -0.0093646" euler=" -1.71188 -0.186636 0" class="wrap" size="0.0218 0.1" type="cylinder" />
    <site name="addmagDist_l_AMdist_at_femshaft_l_sidesite" pos="-0.00019 -0.26074 -0.00936" />
    <geom name="AMmid_at_femshaft_l" pos=" 0.0230125 -0.160711 -0.0205842" euler=" -1.61139 -0.13656 0" class="wrap" size="0.0214 0.06" type="cylinder" />
    <site name="addmagMid_l_AMmid_at_femshaft_l_sidesite" pos="-0.00839 -0.16071 -0.02058" />
    <geom name="AMprox_at_femshaft_l" pos=" 0.00518299 -0.0728948 -0.025403" euler=" -1.61126 -0.18656 0" class="wrap" size="0.0211 0.035" type="cylinder" />
    <site name="addmagProx_l_AMprox_at_femshaft_l_sidesite" pos="-0.02592 -0.07289 -0.02540" />
    <geom name="AL_at_femshaft_l" pos=" 0.0307327 -0.231909 -0.0151137" euler=" -1.77711 -0.136489 0" class="wrap" size="0.0201 0.05" type="cylinder" />
    <site name="addlong_l_AL_at_femshaft_l_sidesite" pos="0.00063 -0.23191 -0.01511" />
    <geom name="AB_at_femshaft_l" pos=" 0.0146434 -0.112595 -0.023365" euler=" -1.66157 -0.186644 0" class="wrap" size="0.0165 0.035" type="cylinder" />
    <site name="addbrev_l_AB_at_femshaft_l_sidesite" pos="-0.01186 -0.11259 -0.02337" />
    <geom name="KnExtVL_at_fem_l" pos=" 0.00188828 -0.402732 -0.00209111" euler=" 0.0623366 -0.0507601 0" class="wrap" size="0.025 0.05" type="cylinder" />
    <site name="vaslat_l_KnExtVL_at_fem_l_sidesite" pos="0.03689 -0.40273 -0.00209" />
    <geom name="KnExt_at_fem_l" pos=" 0.00358828 -0.402732 -0.00209111" euler=" 0.0623366 -0.0507601 0" class="wrap" size="0.025 0.05" type="cylinder" />
    <site name="vasmed_l_KnExt_at_fem_l_sidesite" pos="0.03859 -0.40273 -0.00209" />
    <site name="vasint_l_KnExt_at_fem_l_sidesite" pos="0.03859 -0.40273 -0.00209" />
    <site name="recfem_l_KnExt_at_fem_l_sidesite" pos="0.03859 -0.40273 -0.00209" />
    <geom name="GasMed_at_condyles_l" pos=" 0.005 -0.41 0" euler=" 0 0 0" class="wrap" size="0.025 0.05" type="cylinder" />
    <site name="gasmed_l_GasMed_at_condyles_l_sidesite" pos="-0.01 -0.35 0" />
    <geom name="GasLat_at_condyles_l" pos=" 0.005 -0.41 0" euler=" 0 0 0" class="wrap" size="0.026 0.05" type="cylinder" />
    <site name="gaslat_l_GasLat_at_condyles_l_sidesite" pos="-0.07240 -0.41 0" />

    <site name="addbrev_l-P2" pos="-0.002 -0.118 -0.0249" />
    <site name="addlong_l-P2" pos="0.01126 -0.23937 -0.01583" />
    <site name="addmagDist_l-P2" pos="0.01125 -0.2625 -0.0193" />
    <site name="addmagIsch_l-P2" pos="0.00481 -0.38797 0.03273" />
    <site name="addmagMid_l-P2" pos="0.00242 -0.1624 -0.02922" />
    <site name="addmagProx_l-P2" pos="-0.01527 -0.07886 -0.03202" />
    <site name="bfsh_l-P1" pos="0.005 -0.2111 -0.0234" />
    <site name="gaslat_l-P1" pos="0.002 -0.381 -0.02059" />
    <site name="gasmed_l-P1" pos="0.006 -0.385 0.022" />
    <site name="glmax1_l-P3" pos="-0.0444 -0.0326 -0.0302" />
    <site name="glmax1_l-P4" pos="-0.0277 -0.0566 -0.047" />
    <site name="glmax2_l-P3" pos="-0.045 -0.0584 -0.0252" />
    <site name="glmax2_l-P4" pos="-0.0156 -0.1016 -0.0419" />
    <site name="glmax3_l-P3" pos="-0.0281 -0.1125 -0.0094" />
    <site name="glmax3_l-P4" pos="-0.006 -0.1419 -0.0411" />
    <site name="glmed1_l-P2" pos="-0.0218 -0.0117 -0.0555" />
    <site name="glmed2_l-P2" pos="-0.0258 -0.0058 -0.0527" />
    <site name="glmed3_l-P2" pos="-0.0309 -0.0047 -0.0518" />
    <site name="glmin1_l-P2" pos="-0.0072 -0.0104 -0.056" />
    <site name="glmin2_l-P2" pos="-0.0096 -0.0104 -0.056" />
    <site name="glmin3_l-P2" pos="-0.0135 -0.0083 -0.055" />
    <site name="iliacus_l-P3" pos="-0.0023 -0.0565 -0.0139" />
    <site name="iliacus_l-P4" pos="-0.0122 -0.0637 -0.0196" />
    <site name="piri_l-P3" pos="-0.0148 -0.0036 -0.0437" />
    <site name="psoas_l-P3" pos="-0.0132 -0.0467 -0.0046" />
    <site name="psoas_l-P4" pos="-0.0235 -0.0524 -0.0088" />
    <site name="sart_l-P2" pos="-0.003 -0.3568 0.0421" />
    <site name="tfl_l-P2" pos="0.0294 -0.0995 -0.0597" />
    <site name="tfl_l-P3" pos="0.0107 -0.405 -0.0324" />
    <site name="vasint_l-P1" pos="0.029 -0.1924 -0.031" />
    <site name="vasint_l-P2" pos="0.0335 -0.2084 -0.0285" />
    <site name="vaslat_l-P1" pos="0.0048 -0.1854 -0.0349" />
    <site name="vaslat_l-P2" pos="0.0269 -0.2591 -0.0409" />
    <site name="vasmed_l-P1" pos="0.014 -0.2099 -0.0188" />
    <site name="vasmed_l-P2" pos="0.0356 -0.2769 -0.0009" />
    <joint name="hip_flexion_l" type="hinge" pos="0 0 0" axis="0 0 1" limited="true" range="-0.523599   2.0944" ref="0" class="hip" />
    <joint name="hip_adduction_l" type="hinge" pos="0 0 0" axis="      -1       -0       -0" limited="true" range="-0.872665 0.523599" ref="0" class="hip" />
    <joint name="hip_rotation_l" type="hinge" pos="0 0 0" axis="      -0       -1       -0" limited="true" range="-0.698132 0.698132" ref="0" class="hip" />
    <body name="tibia_l" pos="-4.6e-07 -0.404425 0.00126526" quat="1.0 0 0 0">

      <geom name="l_tibia" type="mesh" mesh="l_tibia" class="bone" />
      <geom name="l_fibula" type="mesh" mesh="l_fibula" class="bone" />
      <geom name="tibia_skin_l" size="0.048" class="skin" fromto="0 0 0 -0.01 -0.35 -0.005" />

      <inertial pos="       0  -0.1867        0" mass="3.7075" fullinertia="  0.0504   0.0051   0.0511        0        0        0" />
      <geom name="BF140_at_gastroc_l" pos=" -0.039 -0.06 0" euler=" 0 0 0" class="wrap" size="0.029 0.075" type="cylinder" />
      <site name="bfsh_l_BF140_at_gastroc_l_sidesite" pos="-0.03900 -0.02100 0.00000" />
      <geom name="ST_at_condyles_l" pos=" -0.002 -0.0205 0" euler=" 0 0.2 0" class="wrap" size="0.0425 0.05" type="cylinder" />
      <site name="semiten_l_ST_at_condyles_l_sidesite" pos="-0.05450 -0.02050 0.00000" />
      <geom name="SM_at_condyles_l" pos=" -0.001 -0.02 0" euler=" 0 0.1 0" class="wrap" size="0.0345 0.05" type="cylinder" />
      <site name="semimem_l_SM_at_condyles_l_sidesite" pos="-0.04550 -0.02000 0.00000" />
      <geom name="GR_at_condyles_l" pos=" -0.003 -0.02 0" euler=" 0 0.4 0" class="wrap" size="0.036 0.05" type="cylinder" />
      <site name="grac_l_GR_at_condyles_l_sidesite" pos="-0.04900 -0.02000 0.00000" />
      <geom name="GasMed_at_shank_l" pos=" -0.0074 -0.074 0.0033" euler=" -2.96723 -0.0279725 -1.47812" class="wrap" size="0.059 0.05" type="cylinder" />
      <site name="gasmed_l_GasMed_at_shank_l_sidesite" pos="-0.07640 -0.07400 0.00330" />
      <geom name="GasLat_at_shank_l" pos=" -0.0074 -0.074 0.0033" euler=" -2.96723 0.279725 -1.47812" class="wrap" size="0.055 0.05" type="cylinder" />
      <site name="gaslat_l_GasLat_at_shank_l_sidesite" pos="-0.07240 -0.07400 0.00330" />
      <site name="bflh_l-P2" pos="-0.03436 -0.03648 -0.03618" />
      <site name="bflh_l-P3" pos="-0.02704 -0.05008 -0.03476" />
      <site name="bfsh_l-P2" pos="-0.02866 -0.03284 -0.03204" />

      <site name="grac_l-P2" pos="-0.01842 -0.04755 0.02961" />
      <site name="grac_l-P3" pos="0.00178 -0.06962 0.01573" />
      <site name="perbrev_l-P1" pos="-0.0243 -0.2532 -0.0251" />
      <site name="perbrev_l-P2" pos="-0.0339 -0.3893 -0.0249" />
      <site name="perbrev_l-P3" pos="-0.0285 -0.4004 -0.0255" />
      <site name="perlong_l-P1" pos="-0.02 -0.1373 -0.0282" />
      <site name="perlong_l-P2" pos="-0.0317 -0.39 -0.0237" />
      <site name="perlong_l-P3" pos="-0.0272 -0.4014 -0.024" />
      <site name="recfem_l-P5" pos="0.0326 -0.06312 0.00047" />
      <site name="sart_l-P3" pos="-0.0251 -0.0401 0.0365" />
      <site name="sart_l-P4" pos="-0.0159 -0.0599 0.0264" />
      <site name="sart_l-P5" pos="0.0136 -0.081 0.0026" />
      <site name="semimem_l-P2" pos="-0.027 -0.041 0.0196" />
      <site name="semiten_l-P2" pos="-0.0312 -0.0508 0.0229" />
      <site name="semiten_l-P3" pos="0.0019 -0.0773 0.0117" />
      <site name="soleus_l-P1" pos="-0.0076 -0.0916 -0.0098" />
      <site name="tfl_l-P4" pos="0.0108 -0.041 -0.0346" />
      <site name="tibant_l-P1" pos="0.0154 -0.1312 -0.0162" />
      <site name="tibant_l-P2" pos="0.0251 -0.1906 -0.0128" />
      <site name="tibant_l-P3" pos="0.0233 -0.3659 0.0132" />
      <site name="tibpost_l-P1" pos="-0.0041 -0.1304 -0.0103" />
      <site name="tibpost_l-P2" pos="-0.0164 -0.3655 0.0175" />
      <site name="vasint_l-P5" pos="0.03257 -0.0632 -0.00043" />
      <site name="vaslat_l-P5" pos="0.03254 -0.06338 -0.00511" />
      <site name="vasmed_l-P5" pos="0.0319 -0.06357 0.00678" />
      <joint name="knee_angle_l_translation3" type="slide" pos="-0.00809 -0.003535 0.001485" axis="-0.992246 -0.123982 -0.00878916" limited="true" range="-0.00365968 0.00187973" ref="0" />
      <joint name="knee_angle_l_translation2" type="slide" pos="-0.00809 -0.003535 0.001485" axis="-0.992246 -0.123982 -0.00878916" limited="true" range="-0.006792 -7.69254e-11" ref="0" />
      <joint name="knee_angle_l_translation1" type="slide" pos="-0.00809 -0.003535 0.001485" axis="-0.124293 0.989762 0.0701648" limited="true" range="9.53733e-08 0.00159883" ref="0" />
      <joint name="knee_angle_l" type="hinge" pos="-0.00809 -0.003535 0.001485" axis="3.98373e-10 0.0707131 -0.997497" limited="true" range="       0   2.4436" ref="0" />
      <joint name="knee_angle_l_rotation2" type="hinge" pos="-0.00809 -0.003535 0.001485" axis="-0.992246 -0.123982 -0.00878916" limited="true" range="-0.00167821 0.0335354" ref="0" />
      <joint name="knee_angle_l_rotation3" type="hinge" pos="-0.00809 -0.003535 0.001485" axis="-0.124293 0.989762 0.0701648" limited="true" range="-0.262788 -1.08939e-08" ref="0" />

      <site name="edl_l-P1" pos="-0.016 -0.1157 -0.0205" />
      <site name="edl_l-P2" pos="0.0164 -0.376 -0.0112" />
      <site name="ehl_l-P1" pos="-0.014 -0.155 -0.0189" />
      <site name="ehl_l-P2" pos="0.0071 -0.2909 -0.0164" />
      <site name="ehl_l-P3" pos="0.02 -0.3693 0.0028" />
      <site name="fdl_l-P1" pos="-0.0023 -0.1832 0.0018" />
      <site name="fdl_l-P2" pos="-0.0176 -0.3645 0.0124" />
      <site name="fhl_l-P1" pos="-0.031 -0.2163 -0.02" />
      <site name="fhl_l-P2" pos="-0.0242 -0.3671 0.0076" />
      <body name="talus_l" pos="   -0.01     -0.4        0" quat="1.0 6.036754011562992e-18 -1.5193252867388614e-18 -2.498419531737724e-19">
        <geom name="l_talus" type="mesh" mesh="l_talus" class="bone" />
        <joint name="ankle_angle_l" type="hinge" pos="0 0 0" axis="0.105014 0.174022 0.979126" limited="true" range="-0.698132 0.523599" ref="0" class="ankle" />
        <body name="calcn_l" pos="-0.04877 -0.04195 -0.00792" quat="1.0 5.320429553087796e-19 -1.609289071159989e-17 -2.1848634538867752e-17">
          <geom name="l_foot" type="mesh" mesh="l_foot" class="bone" />
          <geom name="calcn_skin_1_l" size="0.028" fromto="0.015 0.015 0.008 0.045 0.02 0.005" class="skin"/>
          <geom name="calcn_skin_2_l" size="0.012" fromto="0.07 0.015 -0.025 0.14 0.00 -0.038" class="skin"/>
          <geom name="calcn_skin_3_l" size="0.012" fromto="0.07 0.015 0.025 0.18 0.00 0.03" class="skin"/>
          <site name="edl_l-P3" pos="0.0919 0.036 -0.0008" />
          <site name="edl_l-P4" pos="0.1616 0.0055 -0.013" />
          <site name="ehl_l-P4" pos="0.097 0.0389 0.0211" />
          <site name="ehl_l-P5" pos="0.1293 0.0309 0.0257" />
          <site name="ehl_l-P6" pos="0.1734 0.0139 0.028" />
          <site name="fdl_l-P3" pos="0.0436 0.0315 0.028" />
          <site name="fdl_l-P4" pos="0.0708 0.0176 0.0263" />
          <site name="fdl_l-P5" pos="0.1658 -0.0081 -0.0116" />
          <site name="fhl_l-P3" pos="0.0374 0.0276 0.0241" />
          <site name="fhl_l-P4" pos="0.1038 0.0068 0.0256" />
          <site name="fhl_l-P5" pos="0.1726 -0.0053 0.0269" />
          <site name="gaslat_l-P2" pos="0.0044 0.031 0.0053" />
          <site name="gasmed_l-P2" pos="0.0044 0.031 0.0053" />
          <site name="perbrev_l-P4" pos="0.0471 0.027 -0.0233" />
          <site name="perbrev_l-P5" pos="0.0677 0.0219 -0.0343" />
          <site name="perlong_l-P4" pos="0.0438 0.023 -0.0221" />
          <site name="perlong_l-P5" pos="0.0681 0.0106 -0.0284" />
          <site name="perlong_l-P6" pos="0.0852 0.0069 -0.0118" />
          <site name="perlong_l-P7" pos="0.1203 0.0085 0.0184" />
          <site name="soleus_l-P2" pos="0.0044 0.031 0.0053" />
          <site name="tibant_l-P4" pos="0.1166 0.0178 0.0305" />
          <site name="tibpost_l-P3" pos="0.0417 0.0334 0.0286" />
          <site name="tibpost_l-P4" pos="0.0772 0.0159 0.0281" />
          <joint name="subtalar_angle_l" type="hinge" pos="0 0 0" axis="-0.78718 -0.604747 -0.120949" limited="true" range="-0.349066 0.349066" ref="0" class="ankle" />
          <body name="toes_l" pos="  0.1788   -0.002 -0.00108" quat="1.0 1.314867274624753e-31 2.6810890689525335e-17 3.939849802505862e-32">
            <geom name="l_bofoot" type="mesh" mesh="l_bofoot" class="bone" />
            <geom name="toes_skin_1_l" size="0.01" fromto="0.02 0.00 0.032 -0.02 0.00 -0.042" class="skin"/>
            <geom name="toes_skin_2_l" size="0.012" fromto="0.065 -0.002 0.022 0.012 -0.002 -0.045" class="skin"/>
            <site name="edl_l-P5" pos="0.0003 0.0047 -0.0153" />
            <site name="edl_l-P6" pos="0.0443 -0.0004 -0.025" />
            <site name="ehl_l-P7" pos="0.0298 0.0041 0.0245" />
            <site name="ehl_l-P8" pos="0.0563 0.0034 0.0186" />
            <site name="fdl_l-P6" pos="-0.0019 -0.0078 -0.0147" />
            <site name="fdl_l-P7" pos="0.0285 -0.0071 -0.0215" />
            <site name="fdl_l-P8" pos="0.0441 -0.006 -0.0242" />
            <site name="fhl_l-P6" pos="0.0155 -0.0064 0.0265" />
            <site name="fhl_l-P7" pos="0.0562 -0.0102 0.0181" />
            <joint name="mtp_angle_l" type="hinge" pos="0 0 0" axis="-0.580954 2.6299e-15 -0.813936" limited="true" range="-0.523599 0.523599" ref="0" class="toe" />
          </body>
        </body>
      </body>

    </body>
    <body name="patella_l" pos="-0.00809 -0.40796        0" quat="1.0 0.0 0.0 0.0">
      <geom name="l_patella" type="mesh" mesh="l_patella" class="bone" />
      <site name="recfem_l-P2" pos="0.01 0.049 -0.0007" />
      <site name="recfem_l-P3" pos="0.0121 0.0437 0.001" />
      <site name="recfem_l-P4" pos="0.005 0.00247 -3e-005" />
      <site name="vasint_l-P3" pos="0.0058 0.048 0.0006" />
      <site name="vasint_l-P4" pos="0.005 0.00247 0.00039" />
      <site name="vaslat_l-P3" pos="0.0103 0.0423 -0.0141" />
      <site name="vaslat_l-P4" pos="0.005 0.00247 -0.00733" />
      <site name="vasmed_l-P3" pos="0.0063 0.0445 0.017" />
      <site name="vasmed_l-P4" pos="0.005 0.00247 0.0085" />
      <joint name="knee_angle_l_beta_translation2" type="slide" pos="0 0 0" axis="0 1 0" limited="true" range="-0.0408267 -0.0108281" ref="0" />
      <joint name="knee_angle_l_beta_translation1" type="slide" pos="0 0 0" axis="1 0 0" limited="true" range="-0.0227731 0.0524192" ref="0" />
      <joint name="knee_angle_l_beta_rotation1" type="hinge" pos="0 0 0" axis="0 0 1" limited="true" range="-1.79241 0.010506" ref="0" />
    </body>
  </body>
</mujoco>