<mujoco>
<!-- =================================================
    Copyright 2019 Vikash Kumar
    Model   :: Objects (MuJoCoV2.0)
    Author  :: Vikash Kumar (vikashplus@gmail.com), Sudeep Dasari (sdasari@andrew.cmu.edu )
    Details :: https://github.com/vikashplus/object_sim
    License :: Under Apache License, Version 2.0 (the "License"); you may not use this file except in compliance with the License. You may obtain a copy of the License at http://www.apache.org/licenses/LICENSE-2.0 Unless required by applicable law or agreed to in writing, software distributed under the License is distributed on an "AS IS" BASIS, WITHOUT WARRANTIES OR CONDITIONS OF ANY KIND, either express or implied. See the License for the specific language governing permissions and limitations under the License.
====================================================== -©vk©-->
    <body name="waterbottle" pos="0.30 -0.28 0.94" quat="1 0.0 0.0 0.0">
        <geom name="waterbottle_visual" type="mesh" mesh="waterbottle" rgba="1 0 0 0.0" />
        <geom name="waterbottle_contact0" type="mesh" mesh="waterbottle_contact0" rgba="0.25 0.23 0.2 1" />
        <geom name="waterbottle_contact1" type="mesh" mesh="waterbottle_contact1" rgba="0.31 0.29 0.75 1" />
        <joint name="objTx" pos="0 0 0" axis="1 0 0" limited="true" type="slide" range="-1.20 1.55" damping="0.001" />
        <joint name="objTy" pos="0 0 0" axis="0 1 0" limited="true" type="slide" range="-1.10 1.20" damping="0.001" />
        <joint name="objTz" pos="0 0 0" axis="0 0 1" limited="true" type="slide" range="-1.10 1.35" damping="0.001" />
        <joint name="objRx" pos="0 0 0" axis="1 0 0" limited="false" damping="0.001" />
        <joint name="objRy" pos="0 0 0" axis="0 1 0" limited="false" damping="0.001" />
        <joint name="objRz" pos="0 0 0" axis="0 0 1" limited="false" damping="0.001" />
        <site name="Object" pos="0 0 0" size="0.005 0.005 0.005" group="4" />
        <site name="waterbottle_up" pos="0 0 0.07" size="0.005 0.005 0.005" group="4" />
        <site name="waterbottle_down" pos="0 0 -0.07" size="0.005 0.005 0.005" group="4" />
    </body>

    <body name="target" pos="0.30 -0.28 0.94" quat="1 0.0 0.0 0.0">
        <geom name="target_0" type="mesh" mesh="waterbottle_contact0" rgba="0.25 0.23 0.2 0.3" contype="0" conaffinity="0"/>
        <geom name="target_1" type="mesh" mesh="waterbottle_contact1" rgba="0.31 0.29 0.75 0.3" contype="0" conaffinity="0"/>
        <site name="target_indicator" pos="0 0 0" type="sphere" size="0.001" rgba="0.2 1.7 0.2 0.1"/>
    </body>

</mujoco>