<mujoco>
  <body name="clavicle_r" pos="0 0 0.0335" quat="0.991444821419641 0.0 -0.1305264957017392 0.0">
    <geom name="clavicle" type="mesh" mesh="clavicle" class="bone" />
    <site name="DELT1_r-P4" pos="-0.014 0.01106 0.08021" />
    <site name="PECM1_r-P3" pos="0.003255 -0.02202 0.10118" />
    <site name="PECM1_r-P4" pos="0.00321 -0.00013 0.05113" />

    <site name="cleid_mast-P1" pos="0.00388 0.00542 0.0352" />
    <site name="cleid_occ-P1" pos="0.00388 0.00542 0.0352" />
    <joint name="sternoclavicular_r2_r" type="hinge" pos="0 0 0" axis="  0.0153 0.989299  -0.1451" limited="true" range="-99999.9  99999.9" ref="0" />
    <joint name="sternoclavicular_r3_r" type="hinge" pos="0 0 0" axis="-0.994473        0 -0.104997" limited="true" range="-99999.9  99999.9" ref="0" />
    <body name="clavphant_r" pos="-0.01433  0.02007 0.135535" quat="1.0 0.0 0.0 0.0">
      <inertial mass="0.001" pos="0.000000 0.000000 0.000000" diaginertia="1e-7 1e-7 1e-7" />
      <joint name="unrotscap_r3_r" type="hinge" pos="0 0 0" axis="-0.994473        0 -0.104997" limited="true" range="-99999.9  99999.9" ref="0" />
      <joint name="unrotscap_r2_r" type="hinge" pos="0 0 0" axis="  0.0153 0.989299  -0.1451" limited="true" range="-99999.9  99999.9" ref="0" />
      <body name="scapula_r" pos="0 0 0" quat="0.9848073927247508 0.0 0.17365022094624102 0.0">
        <geom name="scapula" type="mesh" mesh="scapula" class="bone" />
        <geom name="Deltoid2_r" pos="-0.00580 -0.03780 0.00960" class="wrap" size="0.03500" type="sphere" />
        <site name="DELT2_r_Deltoid2_r_sidesite" pos="-0.00580 -0.03780 0.05460" />
        <geom name="TRIlongglen_r" pos="-0.03590 -0.03090 -0.01320" euler="1.37532 -0.29461 2.43596" class="wrap" size="0.00300 0.01500" type="cylinder" />

        <site name="levator_scap-P1" pos="-0.066 0.005 -0.091" />
        <site name="SerrAnt1_1_R-P6" pos="-0.055 0.01 -0.085" />
        <site name="SerrAnt2_1_R-P6" pos="-0.088 -0.032 -0.096" />
        <site name="SerrAnt2_2_R-P6" pos="-0.055 0.01 -0.085" />
        <site name="SerrAnt3_1_R-P9" pos="-0.1 -0.09 -0.096" />
        <site name="SerrAnt4_1_R-P9" pos="-0.102 -0.12 -0.078" />
        <site name="SerrAnt5_1_R-P9" pos="-0.102 -0.12 -0.078" />
        <site name="SerrAnt6_1_R-P9" pos="-0.102 -0.12 -0.078" />
        <site name="SerrAnt7_1_R-P9" pos="-0.102 -0.12 -0.078" />
        <site name="SerrAnt8_1_R-P9" pos="-0.102 -0.12 -0.078" />
        <site name="SerrAnt9_1_R-P9" pos="-0.102 -0.12 -0.078" />

        <site name="DELT1_r-P3" pos="0.04347 -0.03202 0.00499" />
        <site name="DELT2_r-P3" pos="5e-005 0.00294 0.02233" />
        <site name="DELT2_r-P4" pos="-0.01078 -0.00034 0.0062" />
        <site name="DELT3_r-P1" pos="-0.05573 0.00122 -0.02512" />
        <site name="DELT3_r-P2" pos="-0.07247 -0.03285 0.01233" />
        <site name="SUPSP_r-P2" pos="-0.01918 0.00127 -0.01271" />
        <site name="SUPSP_r-P3" pos="-0.044 -0.01512 -0.05855" />
        <site name="INFSP_r-P2" pos="-0.07382 -0.05476 -0.04781" />
        <site name="SUBSC_r-P2" pos="-0.01831 -0.05223 -0.02457" />
        <site name="SUBSC_r-P3" pos="-0.07246 -0.03943 -0.06475" />
        <site name="TMIN_r-P2" pos="-0.09473 -0.07991 -0.04737" />
        <site name="TMIN_r-P3" pos="-0.09643 -0.08121 -0.05298" />
        <site name="TMAJ_r-P4" pos="-0.10264 -0.10319 -0.05829" />
        <site name="TMAJ_r-P5" pos="-0.10489 -0.10895 -0.07117" />
        <site name="LAT1_r-P4" pos="-0.08052 -0.06821 -0.02908" />
        <site name="LAT1_r-P5" pos="-0.10925 -0.07239 -0.07422" />
        <site name="LAT2_r-P4" pos="-0.08345 -0.08695 -0.02453" />
        <site name="LAT2_r-P5" pos="-0.11524 -0.10749 -0.08863" />
        <site name="LAT3_r-P4" pos="-0.08438 -0.11598 -0.02995" />
        <site name="LAT3_r-P5" pos="-0.11279 -0.13833 -0.08911" />
        <site name="CORB_r-P1" pos="0.0125 -0.04127 -0.02652" />
        <site name="CORB_r-P2" pos="0.00483 -0.06958 -0.01563" />
        <site name="TRIlong_r-P1" pos="-0.04565 -0.04073 -0.01377" />
        <site name="BIClong_r-P1" pos="-0.03123 -0.02353 -0.01305" />
        <site name="BIClong_r-P2" pos="-0.02094 -0.01309 -0.00461" />
        <site name="BICshort_r-P1" pos="0.01268 -0.03931 -0.02625" />
        <site name="BICshort_r-P2" pos="0.00093 -0.06704 -0.01593" />
        <joint name="acromioclavicular_r2_r" type="hinge" pos="0 0 0" axis="0.157095 0.947269 -0.279291" limited="true" range="-99999.9  99999.9" ref="0" />
        <joint name="acromioclavicular_r3_r" type="hinge" pos="0 0 0" axis="-0.754084 0.297594 0.585487" limited="true" range="-99999.9  99999.9" ref="0" />
        <joint name="acromioclavicular_r1_r" type="hinge" pos="0 0 0" axis="  0.6377   0.1186   0.7611" limited="true" range="-99999.9  99999.9" ref="0" />
        <body name="scapphant_r" pos="-0.00955   -0.034    0.009" quat="1.0 0.0 0.0 0.0">
          <inertial mass="0.001" pos="0.000000 0.000000 0.000000" diaginertia="1e-7 1e-7 1e-7" />
          <joint name="unrothum_r1_r" type="hinge" pos="0 0 0" axis="  0.6377   0.1186   0.7611" limited="true" range="-99999.9  99999.9" ref="0" />
          <joint name="unrothum_r3_r" type="hinge" pos="0 0 0" axis="-0.754084 0.297594 0.585487" limited="true" range="-99999.9  99999.9" ref="0" />
          <joint name="unrothum_r2_r" type="hinge" pos="0 0 0" axis="0.157095 0.947269 -0.279291" limited="true" range="-99999.9  99999.9" ref="0" />
          <body name="humphant_r" pos="0 0 0" quat="1.0 0.0 0.0 0.0">
            <inertial mass="0.001" pos="0.000000 0.000000 0.000000" diaginertia="1e-7 1e-7 1e-7" />
            <joint name="elv_angle_r" type="hinge" pos="0 0 0" axis="  0.0048 0.999089   0.0424" limited="true" range="-1.65806  2.26893" ref="0" user="1" />
            <body name="humphant1_r" pos="0 0 0" quat="1.0 0.0 0.0 0.0">
              <inertial mass="0.001" pos="0.000000 0.000000 0.000000" diaginertia="1e-7 1e-7 1e-7" />
              <joint name="shoulder_elv_r" type="hinge" pos="0 0 0" axis="-0.998261   0.0023 0.058898" limited="true" range="       0  3.14159" ref="0" user="1" />
              <joint name="shoulder1_r2_r" type="hinge" pos="0 0 0" axis="  0.0048 0.999089   0.0424" limited="true" range="-99999.9  99999.9" ref="0" />
              <body name="humerus_r" pos="0 0 0" quat="1.0 0.0 0.0 0.0">
                <geom name="humerus" type="mesh" mesh="humerus" class="bone" />
                <inertial pos="0.018064 -0.140141 -0.012746" mass="1.99757" diaginertia="0.0122776 0.00255133 0.0125789" />
                <geom name="Elbow_Ulna_r" pos="-0.00500 -0.29000 -0.03300" class="wrap" size="0.01500" type="sphere" />
                <site name="FDSL_r_Elbow_Ulna_r_sidesite" pos="0.02000 -0.29000 -0.03300" />
                <site name="FDSR_r_Elbow_Ulna_r_sidesite" pos="0.02000 -0.29000 -0.03300" />
                <site name="FDSM_r_Elbow_Ulna_r_sidesite" pos="0.02000 -0.29000 -0.03300" />
                <site name="FDSI_r_Elbow_Ulna_r_sidesite" pos="0.02000 -0.29000 -0.03300" />
                <site name="FCU_r_Elbow_Ulna_r_sidesite" pos="0.02000 -0.29000 -0.03300" />
                <site name="PL_r_Elbow_Ulna_r_sidesite" pos="0.02000 -0.29000 -0.03300" />
                <site name="FCR_r_Elbow_Ulna_r_sidesite" pos="0.02000 -0.29000 -0.03300" />
                <site name="PT_r_Elbow_Ulna_r_sidesite" pos="0.02000 -0.29000 -0.03300" />
                <geom name="Elbow_Radius_r" pos="-0.00500 -0.30000 0.00500" class="wrap" size="0.02700" type="sphere" />
                <geom name="DELT_TMAJ_LAT_PEC_CORBhh_r" pos="0.00070 0.00000 0.00600" class="wrap" size="0.03000" type="sphere" />
                <site name="DELT3_r_DELT_TMAJ_LAT_PEC_CORBhh_r_sidesite" pos="-0.03930 0.00000 0.00600" />
                <site name="PECM2_r_TMAJ_LAT_PEC_CORBhh_r_sidesite" pos="0.04070 0.00000 0.00600" />
                <geom name="TMAJ_LAT_PEC_CORBhh_r" pos="0.00070 0.00000 0.00600" class="wrap" size="0.03000" type="sphere" />
                <geom name="BIClong_r" pos="0.00330 0.00500 0.00030" class="wrap" size="0.02200" type="sphere" />
                <geom name="ANC_r" pos="0.01340 -0.28610 -0.00080" class="wrap" size="0.02000" type="sphere" />
                <site name="ANC_r_ANC_r_sidesite" pos="-0.01660 -0.28610 -0.00080" />
                <geom name="TRIlonghh_r" pos="-0.00780 -0.00410 -0.00140" class="wrap" size="0.03000" type="sphere" />
                <site name="TRIlong_r_TRIlonghh_r_sidesite" pos="-0.04780 -0.00410 -0.00140" />
                <geom name="LAT_TMAJ2hh_r" pos="-0.00160 0.00920 0.00520" class="wrap" size="0.03000" type="sphere" />
                <geom name="PEC23hh_r" pos="-0.00860 0.00210 -0.00040" class="wrap" size="0.02000" type="sphere" />
                <geom name="SUBSC_r" pos="-0.00250 0.00079 -0.00450" class="wrap" size="0.02000" type="sphere" />
                <site name="SUBSC_r_SUBSC_r_sidesite" pos="0.02750 0.00079 -0.00450" />
                <geom name="SUPSP_r" pos="0.00020 0.00770 0.00430" class="wrap" size="0.02000" type="sphere" />
                <geom name="CORBhum_r" pos="0.00270 -0.12020 -0.00590" euler="-1.60832 0.09599 0.87528" class="wrap" size="0.00800 0.05000" type="cylinder" />
                <site name="CORB_r_CORBhum_r_sidesite" pos="0.00270 -0.12020 -0.02390" />
                <geom name="TRI_r" pos="0.00280 -0.29190 -0.01190" euler="-0.14015 -0.00628 0.15499" class="wrap" size="0.01600 0.05000" type="cylinder" />
                <site name="TRImed_r_TRI_r_sidesite" pos="-0.02320 -0.29190 -0.01190" />
                <site name="TRIlat_r_TRI_r_sidesite" pos="-0.02320 -0.29190 -0.01190" />
                <site name="TRIlong_r_TRI_r_sidesite" pos="-0.02320 -0.29190 -0.01190" />
                <geom name="Elbow_BIC_BRD_r" pos="0.00190 -0.28900 -0.01400" euler="-0.12863 0.13753 0.03072" class="wrap" size="0.01500 0.05000" type="cylinder" />
                <site name="BRD_r_Elbow_BIC_BRD_r_sidesite" pos="0.02690 -0.28900 -0.01400" />
                <site name="BICshort_r_Elbow_BIC_BRD_r_sidesite" pos="0.02690 -0.28900 -0.01400" />
                <site name="BIClong_r_Elbow_BIC_BRD_r_sidesite" pos="0.02690 -0.28900 -0.01400" />
                <geom name="LAT_TMAJhh_r" pos="-0.02240 0.01020 0.00940" euler="-0.30508 -0.01833 -0.68661" class="wrap" size="0.00700 0.02250" type="cylinder" />
                <geom name="PEC3hum_r" pos="0.00090 -0.05510 -0.00040" euler="1.44094 -0.05620 1.75196" class="wrap" size="0.00800 0.05000" type="cylinder" />
                <site name="PECM3_r_PEC3hum_r_sidesite" pos="0.00090 -0.05510 -0.01840" />
                <geom name="PEC12hum_r" pos="0.00200 -0.05080 -0.00170" euler="1.55928 -0.07749 -0.92590" class="wrap" size="0.00900 0.03500" type="cylinder" />
                <site name="PECM1_r_PEC12hum_r_sidesite" pos="0.00200 -0.05080 -0.02070" />
                <geom name="TMAJ_LAThum_r" pos="0.00070 -0.04430 -0.00550" euler="1.53641 -0.06370 1.41424" class="wrap" size="0.00700 0.02000" type="cylinder" />
                <site name="TMAJ_r_TMAJ_LAThum_r_sidesite" pos="0.00070 -0.04430 -0.02250" />
                <site name="LAT3_r_TMAJ_LAThum_r_sidesite" pos="0.00070 -0.04430 -0.02250" />
                <site name="LAT2_r_TMAJ_LAThum_r_sidesite" pos="0.00070 -0.04430 -0.02250" />
                <site name="LAT1_r_TMAJ_LAThum_r_sidesite" pos="0.00070 -0.04430 -0.02250" />
                <geom name="TMINhum_r" pos="0.00300 -0.02550 0.00130" euler="1.47353 0.02290 3.21463" class="wrap" size="0.02150 0.05650" type="cylinder" />
                <site name="TMIN_r_TMINhum_r_sidesite" pos="-0.02850 -0.02550 0.00130" />
                <geom name="infsp_new_r" pos="-0.00190 -0.01900 0.00220" euler="1.52911 -0.34500 -0.65966" class="wrap" size="0.02350 0.05750" type="cylinder" />
                <site name="INFSP_r_infsp_new_r_sidesite" pos="-0.03540 -0.01900 0.00220" />
                <geom name="delt2hum_r" pos="0.00170 -0.09580 0.00110" euler="1.55093 -0.01996 0.05966" class="wrap" size="0.01090 0.06000" type="cylinder" />
                <site name="DELT1_r_delt2hum_r_sidesite" pos="0.02260 -0.09580 0.00110" />


                <site name="DELT1_r-P1" pos="0.00896 -0.11883 0.00585" />
                <site name="DELT1_r-P2" pos="0.01623 -0.11033 0.00412" />
                <site name="DELT2_r-P1" pos="0.00461 -0.13611 0.0056" />
                <site name="DELT2_r-P2" pos=" 0.01902 -0.06101 0.0184515" />
                <site name="DELT3_r-P3" pos="0.00206 -0.07602 0.01045" />
                <site name="SUPSP_r-P1" pos="0.00256 0.01063 0.02593" />
                <site name="INFSP_r-P1" pos="-0.00887 0.00484 0.02448" />
                <site name="SUBSC_r-P1" pos="0.01403 0.0084 -0.01331" />
                <site name="TMIN_r-P1" pos="-0.00127 -0.01259 0.022" />
                <site name="TMAJ_r-P1" pos="0.00998 -0.05419 -0.00568" />
                <site name="TMAJ_r-P2" pos="0.009 -0.054 -0.009" />
                <site name="TMAJ_r-P3" pos="0.009 -0.054 -0.009" />
                <site name="PECM1_r-P1" pos="0.01169 -0.04191 0.0078" />
                <site name="PECM1_r-P2" pos="  0.0191  -0.0301  0.00143" />
                <site name="PECM2_r-P1" pos="0.01274 -0.04289 0.00785" />
                <site name="PECM2_r-P2" pos=" 0.01748 -0.03533  0.00033" />
                <site name="PECM3_r-P1" pos="0.01269 -0.04375 0.0075" />
                <site name="PECM3_r-P2" pos="0.0159175 -0.045833 -0.00378312" />
                <site name="LAT1_r-P1" pos="0.0105 -0.03415 -0.00653" />
                <site name="LAT1_r-P2" pos="0.01 -0.035 -0.00889323" />
                <site name="LAT1_r-P3" pos="0.01 -0.035 -0.009" />
                <site name="LAT2_r-P1" pos="0.00968 -0.04071 -0.00611" />
                <site name="LAT2_r-P2" pos="0.008 -0.043 -0.01" />
                <site name="LAT2_r-P3" pos="0.00799949 -0.0433861 -0.0100971" />
                <site name="LAT3_r-P1" pos="0.01208 -0.03922 -0.00416" />
                <site name="LAT3_r-P2" pos="0.01 -0.041 -0.009" />
                <site name="LAT3_r-P3" pos="0.01 -0.041 -0.009" />
                <site name="CORB_r-P3" pos="0.00743 -0.15048 -0.00782" />
                <site name="TRIlong_r-P2" pos="-0.02714 -0.11441 -0.00664" />
                <site name="TRIlong_r-P3" pos="-0.03184 -0.22637 -0.01217" />
                <site name="TRIlong_r-P4" pos="-0.01743 -0.26757 -0.01208" />
                <site name="TRIlat_r-P1" pos="-0.00599 -0.12646 0.00428" />
                <site name="TRIlat_r-P2" pos="-0.02344 -0.14528 0.00928" />
                <site name="TRIlat_r-P3" pos="-0.03184 -0.22637 -0.01217" />
                <site name="TRIlat_r-P4" pos="-0.01743 -0.26757 -0.01208" />
                <site name="TRImed_r-P1" pos="-0.00838 -0.13695 -0.00906" />
                <site name="TRImed_r-P2" pos="-0.02601 -0.15139 -0.0108" />
                <site name="TRImed_r-P3" pos="-0.03184 -0.22637 -0.01217" />
                <site name="TRImed_r-P4" pos="-0.01743 -0.26757 -0.01208" />
                <site name="ANC_r-P1" pos="-0.00744 -0.28359 0.00979" />
                <site name="BIClong_r-P3" pos="0.02131 0.01793 0.01028" />
                <site name="BIClong_r-P4" pos="0.02378 -0.00511 0.01201" />
                <site name="BIClong_r-P5" pos="0.01345 -0.02827 0.00136" />
                <site name="BIClong_r-P6" pos="0.01068 -0.07736 -0.00165" />
                <site name="BIClong_r-P7" pos="0.01703 -0.12125 0.00024" />
                <site name="BIClong_r-P8" pos="0.0228 -0.1754 -0.0063" />
                <site name="BICshort_r-P3" pos="0.01117 -0.07576 -0.01101" />
                <site name="BICshort_r-P4" pos="0.01703 -0.12125 -0.01079" />
                <site name="BICshort_r-P5" pos="0.0228 -0.1754 -0.0063" />
                <site name="BRA_r-P1" pos="0.0068 -0.1739 -0.0036" />
                <site name="BRA_r-P2" pos="0.01894 -0.28559 -0.01105" />
                <site name="BRD_r-P1" pos="-0.0098 -0.19963 0.00223" />
                <site name="PT_r-P1" pos="0.0036 -0.2759 -0.0365" />
                <site name="ECRL-P1" pos="-0.007300 -0.260900 0.009100" />
                <site name="ECRB-P1" pos="0.013490 -0.290480 0.016980" />
                <site name="ECU-P1" pos="0.000830 -0.289550 0.018800" />
                <site name="FCR-P1" pos="0.007580 -0.278060 -0.037050" />
                <site name="FCU-P1" pos="0.002190 -0.277400 -0.038800" />
                <site name="PL-P1" pos="0.004570 -0.275190 -0.038650" />
                <site name="FDSL-P1" pos="0.004790 -0.278800 -0.037310" />
                <site name="FDSR-P1" pos="0.004790 -0.278800 -0.037310" />
                <site name="FDSM-P1" pos="0.004790 -0.278800 -0.037310" />
                <site name="FDSI-P1" pos="0.004790 -0.278800 -0.037310" />
                <site name="EDCL-P1" pos="-0.000400 -0.288310 0.018700" />
                <site name="EDCR-P1" pos="-0.001560 -0.289360 0.017820" />
                <site name="EDCM-P1" pos="0.000510 -0.289840 0.019490" />
                <site name="EDCI-P1" pos="0.000650 -0.288980 0.018690" />
                <site name="EDM-P1" pos="0.000890 -0.289190 0.018470" />
                <joint name="shoulder_rot_r" type="hinge" pos="0 0 0" axis="  0.0048 0.999089   0.0424" limited="true" range=" -1.5708   2.0944" ref="0" user="1" />
                <body name="ulna_r" pos="  0.0061  -0.2904  -0.0123" quat="1.0 0.0 0.0 0.0">
                  <geom name="ulna" type="mesh" mesh="ulna" class="bone" />
                  <inertial pos="0.00971783 -0.0959509 0.024286" mass="1.1053" diaginertia="0.00541309 0.00115318 0.00494361" />
                  <geom name="PQ2_r" pos="-0.00120 -0.20920 0.04280" euler="1.39138 0.06894 1.52245" class="wrap" size="0.00700 0.05000" type="cylinder" />
                  <site name="PQ_r_PQ2_r_sidesite" pos="0.01580 -0.20920 0.04280" />
                  <site name="TRIlong_r-P5" pos="-0.0219 0.01046 -0.00078" />
                  <site name="TRIlat_r-P5" pos="-0.0219 0.01046 -0.00078" />
                  <site name="TRImed_r-P5" pos="-0.0219 0.01046 -0.00078" />
                  <site name="ANC_r-P2" pos="-0.02532 -0.00124 0.006" />
                  <site name="SUP_r-P3" pos="-0.0136 -0.03384 0.02013" />
                  <site name="BRA_r-P4" pos="-0.0032 -0.0239 0.0009" />
                  <site name="BRA_r-P3" pos="0.00498 -0.01463 0.00128" />
                  <site name="PT_r-P2" pos="0.00846 -0.03373 -0.01432" />
                  <site name="PT_r-P3" pos=" 0.01219 -0.06516 -0.00219" />
                  <site name="PQ_r-P2" pos="0.00193 -0.20972 0.03632" />
                  <site name="ECU-P2" pos="-0.013910 -0.032010 0.029470" />
                  <site name="ECU-P3" pos="-0.017050 -0.054280 0.028680" />
                  <site name="ECU-P4" pos="-0.017930 -0.095730 0.032780" />
                  <site name="FDPL-P1" pos="-0.006280 -0.032140 0.002540" />
                  <site name="FDPR-P1" pos="-0.005020 -0.033740 0.002730" />
                  <site name="FDPM-P1" pos="-0.005220 -0.033270 0.002100" />
                  <site name="FDPI-P1" pos="-0.006470 -0.031760 0.002800" />
                  <site name="EDM-P2" pos="-0.009770 -0.039070 0.030850" />
                  <site name="EDM-P3" pos="-0.007550 -0.082670 0.036460" />
                  <site name="EIP-P1" pos="-0.003940 -0.166520 0.036820" />
                  <site name="EIP-P2" pos="0.001710 -0.174690 0.040490" />
                  <site name="EPL-P1" pos="-0.014120 -0.097060 0.029520" />
                  <site name="SUP_r_SUP_r_sidesite" pos="-0.00764535 -0.0554069 0.0350824" />
                  <joint name="elbow_flexion_r" type="hinge" pos="0 0 0" axis="  0.0494   0.0366 0.998108" limited="true" range="       0  2.26893" ref="0" user="1" />
                  <body name="radius_r" pos="  0.0004 -0.011503 0.019999" quat="1.0 0.0 0.0 0.0">
                    <geom name="radius" type="mesh" mesh="radius" class="bone" />
                    <inertial pos="0.0336341 -0.181559   0.0156" mass="0.23359" diaginertia="0.00043855 8.859e-05 0.00040258" />
                    <geom name="ECU_torus_wrap_r" pos="-0.01630 -0.24170 0.03490" class="wrap" size="0.00300" type="sphere" />
                    <site name="ECU_r_ECU_torus_wrap_r_sidesite" pos="-0.01630 -0.24170 0.03490" />
                    <geom name="PQ1_r" pos="0.02810 -0.19860 0.02880" euler="-1.60762 -0.01274 -2.69025" class="wrap" size="0.01000 0.05000" type="cylinder" />
                    <geom name="SUP_r" pos="0.00450 -0.04370 0.00590" euler="1.44775 0.30404 -2.44102" class="wrap" size="0.00800 0.02000" type="cylinder" />
                    <site name="SUP_r-P1" pos="0.00996 -0.06096 0.00075" />
                    <site name="SUP_r-P2" pos="0.01201 -0.0517 -0.00107" />
                    <site name="BIClong_r-P10" pos="-0.002 -0.0375 -0.002" />
                    <site name="BIClong_r-P9" pos=" 0.00273 -0.0343493 -0.0119845" />
                    <site name="BICshort_r-P7" pos="-0.002 -0.0375 -0.002" />
                    <site name="BICshort_r-P6" pos=" 0.00273 -0.0343493 -0.0119845" />
                    <site name="BRD_r-P2" pos="0.03577 -0.12742 0.02315" />
                    <site name="BRD_r-P3" pos="0.0419 -0.221 0.0224" />
                    <site name="PL_r-P2" pos="0.02531 -0.23915 -0.00276" />
                    <site name="PT_r-P5" pos="0.0254 -0.1088 0.0198" />
                    <site name="PT_r-P4" pos="0.0236 -0.0934 0.0094" />
                    <site name="PQ_r-P1" pos="0.03245 -0.19998 0.01962" />
                    <site name="ECRL-P2" pos="0.031950 -0.134630 0.027790" />
                    <site name="ECRL-P3" pos="0.042430 -0.236840 0.036200" />
                    <site name="ECRB-P2" pos="0.029050 -0.130860 0.023850" />
                    <site name="ECRB-P3" pos="0.035490 -0.228050 0.039370" />
                    <site name="ECU-P5" pos="-0.014210 -0.226960 0.034810" />
                    <site name="FCR-P2" pos="0.021100 -0.219430 0.001270" />
                    <site name="FCU-P2" pos="0.009490 -0.184100 0.000500" />
                    <site name="FCU-P3" pos="0.010820 -0.223270 0.009690" />
                    <site name="PL-P2" pos="0.025310 -0.239150 -0.002760" />
                    <site name="FDSL-P2" pos="0.013770 -0.187180 0.002050" />
                    <site name="FDSR-P2" pos="0.015710 -0.186660 0.002670" />
                    <site name="FDSM-P2" pos="0.018990 -0.187060 0.004240" />
                    <site name="FDSI-P2" pos="0.021450 -0.186230 0.006000" />
                    <site name="FDPL-P2" pos="0.014090 -0.185160 0.008610" />
                    <site name="FDPR-P2" pos="0.015800 -0.186290 0.008030" />
                    <site name="FDPM-P2" pos="0.019060 -0.186440 0.007850" />
                    <site name="FDPI-P2" pos="0.020800 -0.185600 0.009150" />
                    <site name="EDCL-P2" pos="0.001300 -0.038880 0.014050" />
                    <site name="EDCL-P3" pos="0.009930 -0.223040 0.036180" />
                    <site name="EDCR-P2" pos="0.002600 -0.039910 0.015520" />
                    <site name="EDCR-P3" pos="0.008820 -0.223660 0.043000" />
                    <site name="EDCM-P2" pos="0.003160 -0.039480 0.015280" />
                    <site name="EDCM-P3" pos="0.014400 -0.223230 0.042230" />
                    <site name="EDCI-P2" pos="0.002280 -0.039180 0.014830" />
                    <site name="EDCI-P3" pos="0.015330 -0.223140 0.041960" />
                    <site name="EDM-P4" pos="0.004540 -0.226410 0.036780" />
                    <site name="EIP-P3" pos="0.010760 -0.227830 0.037000" />
                    <site name="EPL-P2" pos="0.001240 -0.136680 0.022700" />
                    <site name="EPL-P3" pos="0.027020 -0.218720 0.038280" />
                    <site name="EPL-P4" pos="0.033820 -0.227540 0.046070" />
                    <site name="EPL-P5" pos="0.042340 -0.237710 0.041730" />
                    <site name="EPB-P1" pos="0.019240 -0.146950 0.021140" />
                    <site name="EPB-P2" pos="0.022760 -0.158570 0.026650" />
                    <site name="EPB-P3" pos="0.038310 -0.197220 0.038340" />
                    <site name="EPB-P4" pos="0.049477 -0.230710 0.018454" />
                    <site name="FPL-P1" pos="0.009710 -0.094580 0.017690" />
                    <site name="FPL-P2" pos="0.016580 -0.135250 0.019150" />
                    <site name="FPL-P3" pos="0.018690 -0.179320 0.019880" />
                    <site name="FPL-P4" pos="0.029543 -0.231721 0.015909" />
                    <site name="APL-P1" pos="0.011540 -0.094770 0.016810" />
                    <site name="APL-P2" pos="0.030232 -0.141162 0.029667" />
                    <site name="APL-P3" pos="0.036538 -0.160267 0.030189" />
                    <site name="APL-P4" pos="0.038803 -0.183618 0.023863" />
                    <site name="APL-P5" pos="0.048869 -0.230848 0.023760" />
                    <joint name="pro_sup_r" type="hinge" pos="0 0 0" axis="-0.017161 0.992666 -0.119668" limited="true" range=" -1.5708   1.5708" ref="0" user="1" />
                    <body name="proximal_row" pos="   0.018   -0.242    0.025" quat="1.0 0.0 0.0 0.0" childclass="hand">
                      <geom name="lunate" type="mesh" mesh="lunate" class="bone" />
                      <geom name="scaphoid" type="mesh" mesh="scaphoid" class="bone" />
                      <geom name="pisiform" type="mesh" mesh="pisiform" class="bone" />
                      <geom name="triquetral" type="mesh" mesh="triquetral" class="bone" />

                      <geom name="FPL_ellipsoid_wrap_r" pos="0.02000 -0.02500 -0.00330" class="wrap" size="0.01500" type="sphere" />
                      <site name="PL_r_PL_ellipsoid_wrap_r_sidesite" pos="0.02000 -0.02500 -0.02830" />
                      <geom name="EDCI_torus_wrap_r" pos="0.00900 -0.01490 0.02110" class="wrap" size="0.00350" type="sphere" />
                      <site name="EDCI_r_EDCI_torus_wrap_r_sidesite" pos="-0.01280 -0.01330 0.01480" />
                      <geom name="EDCM_torus_wrap_r" pos="-0.00070 -0.01170 0.01910" class="wrap" size="0.00350" type="sphere" />
                      <site name="EDCM_r_EDCM_torus_wrap_r_sidesite" pos="-0.00070 -0.01170 0.01910" />
                      <geom name="EDCR_torus_wrap_r" pos="-0.00980 -0.01370 0.01660" class="wrap" size="0.00300" type="sphere" />
                      <site name="EDCR_r_EDCR_torus_wrap_r_sidesite" pos="-0.00980 -0.01370 0.01660" />
                      <geom name="EDCL_torus_wrap_r" pos="-0.01280 -0.01330 0.01480" class="wrap" size="0.00400" type="sphere" />
                      <site name="EDCL_r_EDCL_torus_wrap_r_sidesite" pos="-0.01280 -0.01330 0.01480" />
                      <geom name="FCR_torus_wrap_r" pos="0.00320 -0.00450 -0.01900" class="wrap" size="0.00150" type="sphere" />
                      <site name="FCR_r_FCR_torus_wrap_r_sidesite" pos="0.00320 -0.00450 -0.01900" />
                      <geom name="ECRB_torus_wrap_r" pos="0.01260 -0.00950 0.01860" class="wrap" size="0.00200" type="sphere" />
                      <site name="ECRB_r_ECRB_torus_wrap_r_sidesite" pos="0.01260 -0.00950 0.01860" />
                      <geom name="ECRL_torus_wrap_r" pos="0.02220 -0.00960 0.02080" class="wrap" size="0.00800" type="sphere" />
                      <site name="ECRL_r_ECRL_torus_wrap_r_sidesite" pos="0.02220 -0.00960 0.02080" />
                      <geom name="EIP_r" pos="-0.00146 -0.01200 -0.00893" class="wrap" size="0.02374" type="sphere" />
                      <site name="EIP_r_EIP_r_sidesite" pos="-0.01951 -0.00431 0.06366" />
                      <geom name="EDM_ellipsoid_wrap_r" pos="-0.01670 -0.00220 0.00480" euler="2.96270 1.73000 0.11798" class="wrap" size="0.01400 0.01800" type="cylinder" />
                      <site name="EDM_r_EDM_ellipsoid_wrap_r_sidesite" pos="-0.01670 0.00220 0.01500" />
                      <geom name="FDP_ellipsoid_wrap_r" pos="-0.00220 -0.00690 0.00320" euler="-1.46747 1.37000 0.12182" class="wrap" size="0.01300 0.02500" type="cylinder" />
                      <site name="FDPL_r_FDP_ellipsoid_wrap_r_sidesite" pos="-0.00481 -0.03445 -0.02136" />
                      <site name="FDPR_r_FDP_ellipsoid_wrap_r_sidesite" pos="-0.00481 -0.03445 -0.02136" />
                      <site name="FDPM_r_FDP_ellipsoid_wrap_r_sidesite" pos="-0.00481 -0.03445 -0.02136" />
                      <site name="FDPI_r_FDP_ellipsoid_wrap_r_sidesite" pos="-0.00481 -0.03445 -0.02136" />
                      <geom name="FDS_ellipsoid_wrap_r" pos="0.00120 -0.00570 -0.00030" euler="0.00838 1.48000 -0.01710" class="wrap" size="0.01300 0.02500" type="cylinder" />
                      <site name="FDSL_r_FDS_ellipsoid_wrap_r_sidesite" pos="-0.00481 -0.03445 -0.02136" />
                      <site name="FDSR_r_FDS_ellipsoid_wrap_r_sidesite" pos="-0.00481 -0.03445 -0.02136" />
                      <site name="FDSM_r_FDS_ellipsoid_wrap_r_sidesite" pos="-0.00481 -0.03445 -0.02136" />
                      <site name="FDSI_r_FDS_ellipsoid_wrap_r_sidesite" pos="-0.00481 -0.03445 -0.02136" />
                      <geom name="PL_ellipsoid_wrap_r" pos="0.00570 -0.01800 -0.00410" euler="0.00000 1.57000 0.00000" class="wrap" size="0.01250 0.01250" type="cylinder" />
                      <geom name="FCU_torus_wrap_r" pos="-0.01200 -0.01000 -0.00900" euler="0.00000 1.57000 0.00000" class="wrap" size="0.00680 0.02500" type="cylinder" />
                      <site name="FCU_r_FCU_torus_wrap_r_sidesite" pos="-0.01200 -0.01000 -0.02580" />
                      <site name="EPB-P5" pos="0.032222 -0.007688 -0.012443" />
                      <site name="FPL-P5" pos="0.012148 -0.002895 -0.016993" />
                      <site name="APL-P6" pos="0.030130 -0.000650 -0.010897" />
                      <site name="APL-P7" pos="0.031124 -0.006605 -0.012129" />
                      <site name="ADM-P1" pos="-0.009385 -0.011938 -0.013671" />
                      <joint name="deviation_r" type="hinge" pos="0 0 0" axis="-0.819064 -0.135611 -0.557444" limited="true" range="-0.174533 0.436332" ref="0"></joint>
                      <joint name="flexion_r" type="hinge" pos="0 0 0" axis="0.956427 -0.252207 0.147104" limited="true" range="-0.610864 0.610864" ref="0"></joint>
                      <body name="capitate" pos="0.003992 -0.015054 0.002327" quat="1.0 0.0 0.0 0.0">
                        <geom name="capitate" type="mesh" mesh="capitate" class="bone" />
                        <site name="ECRL-P4" pos="0.017170 -0.021220 0.005830" />
                        <site name="ECRB-P4" pos="0.005000 -0.011360 0.008500" />
                        <site name="ECU-P6" pos="-0.022510 -0.014010 -0.001280" />
                        <site name="FCR-P3" pos="0.011240 -0.018440 -0.004180" />
                        <site name="FCU-P4" pos="-0.020360 -0.017650 -0.007520" />
                        <site name="PL-P3" pos="0.009170 -0.018980 -0.017540" />
                        <site name="FDSL-P3" pos="-0.002350 -0.013930 -0.013760" />
                        <site name="FDSR-P3" pos="-0.000820 -0.013440 -0.013590" />
                        <site name="FDSM-P3" pos="0.006800 -0.013770 -0.013990" />
                        <site name="FDSI-P3" pos="0.008890 -0.013660 -0.013870" />
                        <site name="FDPL-P3" pos="-0.000880 -0.010270 -0.011880" />
                        <site name="FDPR-P3" pos="0.001060 -0.011770 -0.011840" />
                        <site name="FDPM-P3" pos="0.003350 -0.012800 -0.011440" />
                        <site name="FDPI-P3" pos="0.008960 -0.011680 -0.012120" />
                        <site name="EPL-P6" pos="0.024280 0.000140 0.006080" />
                        <site name="FPL-P6" pos="0.011131 -0.006455 -0.022573" />
                        <site name="APB-P1" pos="0.004484 -0.005190 -0.012640" />
                        <site name="FPB_opt-P1" pos="0.009590 -0.006670 -0.014810" />
                        <site name="OPP-P1" pos="0.011290 -0.001470 -0.017310" />
                        <site name="ADPt_opt-P1" pos="0.000640 -0.024220 0.001490" />
                        <site name="ADPo_opt-P1" pos="-0.001310 -0.005270 -0.006650" />
                        <joint name="wrist_hand_r1_r" type="hinge" pos="0 0 0" axis="0.899136 -0.349053 -0.26404" limited="true" range="-1 1" ref="0"></joint>
                        <joint name="wrist_hand_r3_r" type="hinge" pos="0 0 0" axis="0.997119   0.0107 -0.075101" limited="true" range="-1 1" ref="0"></joint>
                        <body name="trapezium" pos="0.015293 -0.004569 -0.010308" quat="1.0 0.0 0.0 0.0">
                          <geom name="trapezium" type="mesh" mesh="trapezium" class="bone" />
                          <site name="EPL-P7" pos="0.009221 -0.000721 0.012035" />
                          <site name="APB-P2" pos="0.008014 -0.001309 -0.011754" />
                          <site name="FPB_opt-P2" pos="0.001500 -0.012498 -0.004960" />
                          <site name="palm_site" pos="-0.011 -0.06 -0.03" size="0.001" group="4" />
                          <body name="firstmc1" pos="       0        0        0" quat="1.0 0.0 0.0 0.0">
                            <inertial mass="0.001" pos="0.000000 0.000000 0.000000" diaginertia="1e-7 1e-7 1e-7" />
                            <site name="EPB-P6" pos="0.014430 -0.003370 -0.004050" />
                            <joint name="cmc_flexion" type="hinge" pos="0 0 0" axis="0.042399 0.665286 -0.745384" limited="true" range="-0.785398 0.261799" ref="0"></joint>
                            <body name="firstmc" pos="  0.0072  -0.0054  -0.0025" quat="1.0 0.0 0.0 0.0">
                              <geom name="1mc" type="mesh" mesh="1mc" class="bone" />
                              <geom name="firstmc_skin_1_r" size="0.01" fromto="0 0 0 0.0165 -0.0292 -0.0127" class="skin"/>
                              <geom name="MPthumb_r" pos="0.01770 -0.03050 -0.01430" euler="0.32132 0.11013 -0.83479" class="wrap" size="0.00850 0.01000" type="cylinder" />
                              <site name="EPL_r_MPthumb_r_sidesite" pos="0.01770 -0.03050 0.00420" />
                              <site name="EPB_r_MPthumb_r_sidesite" pos="0.01770 -0.03050 0.00420" />
                              <site name="EPL-P8" pos="0.006560 -0.004300 0.007920" />
                              <site name="EPL-P9" pos="0.021650 -0.024200 -0.005330" />
                              <site name="EPB-P7" pos="0.021730 -0.023030 -0.011410" />
                              <site name="FPL-P7" pos="-0.006080 -0.016240 -0.009400" />
                              <site name="FPL-P8" pos="0.000223 -0.023127 -0.011331" />
                              <site name="APL-P8" pos="0.006290 0.003230 -0.005890" />
                              <site name="APL-P9" pos="0.008270 -0.005860 -0.006040" />
                              <site name="FPB_opt-P3" pos="0.008048 -0.033672 -0.014978" />
                              <site name="OPP-P2" pos="-0.002386 -0.008940 -0.005517" />
                              <site name="OPP-P3" pos="0.012000 -0.028000 -0.017000" />
                              <site name="1stDI_MC1-P1" pos="0.004434 -0.009700 0.003216" />
                              <joint name="cmc_abduction" type="hinge" pos="0 0 0" axis="0.495557 0.731736 0.467959" limited="true" range="-0.436332 0.436332" ref="0"></joint>
                              <body name="proximal_thumb" pos="  0.0165  -0.0292  -0.0127" quat="1.0 0.0 0.0 0.0">
                                <geom name="thumbprox" type="mesh" mesh="thumbprox" class="bone" />
                                <geom name="proximal_thumb_skin_r" size="0.01" fromto="0.003 -0.007 -0.002 0.014 -0.025 -0.0101" class="skin"/>
                                <geom name="IPthumb_r" pos="0.01210 -0.03020 -0.00960" euler="0.30473 0.01292 0.08796" class="wrap" size="0.00450 0.00500" type="cylinder" />
                                <site name="EPL-P10" pos="0.011470 -0.003620 0.001560" />
                                <site name="EPL-P11" pos="0.019210 -0.026500 -0.010380" />
                                <site name="EPB-P8" pos="0.009270 -0.006180 -0.005570" />
                                <site name="FPL-P9" pos="-0.003700 -0.016412 -0.006442" />
                                <site name="FPL-P10" pos="0.005900 -0.026020 -0.011140" />
                                <site name="APB-P3" pos="0.007706 -0.004717 -0.009000" />
                                <site name="APB-P4" pos="0.014800 -0.020000 -0.011000" />
                                <site name="FPB_opt-P4" pos="0.002000 -0.013000 -0.004000" />
                                <site name="ADPt_opt-P2" pos="0.001000 -0.013000 0.001000" />
                                <site name="ADPo_opt-P2" pos="0.001469 -0.012970 -0.000666" />
                                <joint name="mp_flexion" type="hinge" pos="0 0 0" axis="0.084295 0.203488 -0.975442" limited="true" range="-0.698132 0.785398" ref="0"></joint>
                                <body name="distal_thumb" pos="   0.014  -0.0259  -0.0101" quat="1.0 0.0 0.0 0.0">
                                  <geom name="thumbdist" type="mesh" mesh="thumbdist" class="bone" />
                                  <geom name="distal_thumb_skin_r" size="0.007" fromto="0.0025426 -0.00489526 -0.0022617 0.009 -0.016 -0.006" class="skin"/>
                                  <site name="EPL-P12" pos="0.005430 -0.007140 -0.004640" />
                                  <site name="FPL-P11" pos="0.002420 -0.011270 -0.004120" />
                                  <joint name="ip_flexion" type="hinge" pos="0 0 0" axis="0.050102 0.479623 -0.876043" limited="true" range="-0.436332    1.309" ref="0"></joint>
                                </body>
                              </body>
                            </body>
                          </body>
                        </body>
                        <body name="trapezoid" pos="0.009143 -0.004062 -0.002464" quat="1.0 0.0 0.0 0.0">
                          <geom name="trapezoid" type="mesh" mesh="trapezoid" class="bone" />
                        </body>
                        <body name="hamate" pos="-0.010969 -0.002495 -0.00075" quat="1.0 0.0 0.0 0.0">
                          <geom name="hamate" type="mesh" mesh="hamate" class="bone" />
                          <site name="FDM-P1" pos="-0.001738 -0.002578 -0.010279" />
                          <site name="ODM-P1" pos="-0.001738 -0.002578 -0.010279" />
                        </body>
                        <body name="secondmc" pos="0.014685 -0.03762 0.005032" quat="1.0 0.0 0.0 0.0">
                          <geom name="2mc" type="mesh" mesh="2mc" class="bone" />
                          <geom name="secondmc_skin_1_r" size="0.01 0.028" euler="1.42 0.15 -0.1" pos="0 0 -0.001" class="skin"/>
                          <geom name="2ndmcp_FDPI_r" pos="0.00350 -0.02750 0.00362" euler="0.59394 1.50011 -2.23559" class="wrap" size="0.01020 0.01000" type="cylinder" />
                          <site name="FDPI_r_2ndmcp_FDPI_r_sidesite" pos="0.00350 -0.02750 -0.01658" />
                          <geom name="2ndmcp_FDSI_r" pos="0.00350 -0.02750 0.00362" euler="0.59394 1.50011 -2.16578" class="wrap" size="0.01100 0.01000" type="cylinder" />
                          <site name="FDSI_r_2ndmcp_FDSI_r_sidesite" pos="0.00350 -0.02750 -0.01738" />
                          <geom name="2ndmcp_extI_r" pos="0.00350 -0.02500 0.00380" euler="0.59394 1.50011 -1.99125" class="wrap" size="0.00900 0.00500" type="cylinder" />
                          <site name="EIP_r_2ndmcp_extI_r_sidesite" pos="0.00350 -0.02500 0.02280" />
                          <site name="EDCI_r_2ndmcp_extI_r_sidesite" pos="0.00350 -0.02500 0.02280" />
                          <site name="FDSI-P4" pos="-0.004070 -0.000250 -0.004790" />
                          <site name="FDSI-P5" pos="-0.001000 -0.021000 -0.005790" />
                          <site name="FDPI-P4" pos="-0.004320 0.007000 -0.002480" />
                          <site name="FDPI-P5" pos="0.000000 -0.021000 -0.005000" />
                          <site name="EDCI-P4" pos="0.005865 -0.025592 0.013371" />
                          <site name="EIP-P4" pos="-0.010810 0.015000 0.007000" />
                          <site name="EIP-P5" pos="0.004410 -0.027000 0.013000" />
                          <site name="1stPI-P1" pos="-0.006000 0.011000 -0.003000" />
                          <site name="1stPI-P2" pos="-0.003000 -0.025000 0.003000" />
                          <site name="1stDI_MC1-P2" pos="0.009000 -0.026600 0.000000" />
                          <site name="1stDI_MC2-P1" pos="0.003000 0.016000 -0.003000" />
                          <site name="1stDI_MC2-P2" pos="0.008250 -0.025000 -0.002000" />
                          <site name="LUMI-P1" pos="-0.005500 0.022000 -0.014000" />
                          <site name="LUMI-P2" pos="0.005000 -0.022500 -0.006000" />
                          <body name="2proxph" pos="0.003501 -0.028243  0.00362" quat="1.0 0.0 0.0 0.0">
                            <geom name="2proxph" type="mesh" mesh="2proxph" class="bone" />
                            <geom name="2proxph_skin_r" size="0.009 0.018" pos="0.004 -0.0210 0.00362" euler="1.45 0.15 -0.35" class="skin"/>
                            <geom name="Secondpm_r" pos="0.00750 -0.04070 0.00610" euler="0.74194 -1.47393 0.70965" class="wrap" size="0.00400 0.00500" type="cylinder" />
                            <geom name="2ndpm_extI_r" pos="0.00750 -0.04075 0.00730" euler="-2.99394 1.28823 1.41721" class="wrap" size="0.00425 0.00600" type="cylinder" />
                            <site name="EIP_r_2ndpm_extI_r_sidesite" pos="0.00750 -0.04075 0.02155" />
                            <site name="EDCI_r_2ndpm_extI_r_sidesite" pos="0.00750 -0.04075 0.02155" />
                            <geom name="2ndpm_FDPI_r" pos="0.00750 -0.04050 0.00800" euler="-2.99394 1.28823 1.41721" class="wrap" size="0.00800 0.01000" type="cylinder" />
                            <geom name="2ndpm_FDSI_r" pos="0.00750 -0.04100 0.00450" euler="-2.99394 1.28823 1.41721" class="wrap" size="0.00550 0.00500" type="cylinder" />
                            <site name="FDSI-P6" pos="-0.001000 -0.014000 -0.002705" />
                            <site name="FDSI-P6_0" pos="0.004270 -0.035000 0.004000" />
                            <site name="FDPI-P6" pos="0.000000 -0.011000 -0.002775" />
                            <site name="FDPI-P7" pos="0.005810 -0.034000 0.003060" />
                            <site name="EDCI-P5" pos="0.003082 -0.009692 0.011048" />
                            <site name="EDCI-P6" pos="0.007710 -0.038000 0.013000" />
                            <site name="EIP-P6" pos="0.001710 -0.010000 0.011000" />
                            <site name="EIP-P7" pos="0.007140 -0.038000 0.013000" />
                            <site name="1stPI-P3" pos="-0.005000 -0.011000 0.001000" />
                            <site name="1stDI_MC1-P3" pos="0.009000 -0.016000 -0.001000" />
                            <site name="1stDI_MC2-P3" pos="0.009000 -0.016000 -0.001000" />
                            <site name="LUMI-P3" pos="0.005000 -0.010000 -0.005000" />
                            <site name="LUMI-P4" pos="0.005000 -0.016000 -0.005000" />
                            <joint name="2mcp_abduction" type="hinge" pos="0 0 0" axis="0.214609 0.191508 0.957741" limited="true" range="-0.261799 0.261799" ref="0"></joint>
                            <joint name="2mcp_flexion" type="hinge" pos="0 0 0" axis="0.978577 0.0260223 -0.197329" limited="true" range="-0.785398   1.5708" ref="0"></joint>
                            <body name="2midph" pos="0.007517 -0.041273 0.007326" quat="1.0 0.0 0.0 0.0">
                              <geom name="2midph" type="mesh" mesh="2midph" class="bone" />
                              <geom name="2midph_skin_r" size="0.008 0.011" pos="0.0013 -0.012 0.00" euler="1.5 0.14 -0.35" class="skin"/>
                              <geom name="Secondmd_r" pos="0.00360 -0.02430 0.00030" euler="0.50178 -1.41302 0.64734" class="wrap" size="0.00400 0.00500" type="cylinder" />
                              <geom name="2ndmd_extI_r" pos="0.00330 -0.02150 0.00350" euler="-2.75500 1.36537 1.17670" class="wrap" size="0.00400 0.00500" type="cylinder" />
                              <site name="EIP_r_2ndmd_extI_r_sidesite" pos="0.00330 -0.02150 0.01750" />
                              <site name="EDCI_r_2ndmd_extI_r_sidesite" pos="0.00330 -0.02150 0.01750" />
                              <site name="FDSI-P7" pos="0.002280 -0.008000 -0.005000" />
                              <site name="FDPI-P8" pos="0.000000 -0.008000 -0.005000" />
                              <site name="FDPI-P9" pos="0.002000 -0.021000 -0.002000" />
                              <site name="EDCI-P7" pos="0.001230 -0.005000 0.005000" />
                              <site name="EDCI-P8" pos="0.002600 -0.018000 0.006000" />
                              <site name="EIP-P8" pos="0.001150 -0.005000 0.005000" />
                              <site name="EIP-P9" pos="0.002940 -0.018000 0.006000" />
                              <joint name="2pm_flexion" type="hinge" pos="0 0 0" axis="0.976336 0.126712 -0.175394" limited="true" range="       0  1.74533" ref="0"></joint>
                              <body name="2distph" pos="0.003333 -0.024888  0.00122" quat="1.0 0.0 0.0 0.0">
                                <geom name="2distph" type="mesh" mesh="2distph" class="bone" />
                                <geom name="2distph_skin_r" size="0.007 0.007" pos="0.001 -0.008 0.00" euler="1.5 0.14 -0.35" class="skin"/>
                                <site name="FDPI-P10" pos="0.000460 -0.004600 -0.003000" />
                                <site name="EDCI-P9" pos="0.000250 -0.003700 0.002280" />
                                <site name="EIP-P10" pos="0.000000 -0.004000 0.002000" />
                                <joint name="2md_flexion" type="hinge" pos="0 0 0" axis="0.986691 0.147151 0.0749456" limited="true" range="       0  1.39626" ref="0"></joint>
                              </body>
                            </body>
                          </body>
                        </body>
                        <body name="thirdmc" pos="0.000477 -0.039239 0.007377" quat="1.0 0.0 0.0 0.0">
                          <geom name="3mc" type="mesh" mesh="3mc" class="bone" />
                          <geom name="thirdmc_skin_r" size="0.01 0.026" euler="1.42 0.01 0" pos="0 0 0" class="skin"/>
                          <geom name="_3rdmcp_r" pos="0.00160 -0.02710 0.00010" euler="2.57942 -1.44967 2.90615" class="wrap" size="0.00500 0.01000" type="cylinder" />
                          <site name="EDCM_r__3rdmcp_r_sidesite" pos="0.00160 -0.02710 0.01510" />
                          <site name="FDPM_r__3rdmcp_r_sidesite" pos="0.00160 -0.02710 -0.01490" />
                          <site name="FDSM_r__3rdmcp_r_sidesite" pos="0.00160 -0.02710 -0.01490" />
                          <site name="PL-P4" pos="0.001790 0.008280 -0.002450" />
                          <site name="FDSR-P4" pos="-0.009140 0.005440 -0.010850" />
                          <site name="FDSM-P4" pos="0.001280 0.006390 -0.009520" />
                          <site name="FDSM-P5" pos="0.000000 -0.016000 -0.008500" />
                          <site name="FDPR-P4" pos="-0.010400 0.004730 -0.008040" />
                          <site name="FDPM-P4" pos="-0.001280 0.006090 -0.008380" />
                          <site name="FDPM-P5" pos="0.000500 -0.018682 -0.007672" />
                          <site name="EDCM-P4" pos="-0.000690 -0.027000 0.010000" />
                          <site name="2ndPI-P1" pos="-0.006000 0.016000 -0.003000" />
                          <site name="2ndDI-P1" pos="0.003000 0.016000 -0.003000" />
                          <site name="2ndDI-P2" pos="0.007000 -0.021000 0.001000" />
                          <site name="3rdDI-P1" pos="-0.004000 0.016000 -0.003000" />
                          <site name="3rdDI-P2" pos="-0.006000 -0.024000 0.000500" />
                          <site name="LUMR-P1" pos="-0.003149 0.020002 -0.016641" />
                          <site name="LUMM-P1" pos="0.002000 0.022000 -0.016000" />
                          <site name="LUMM-P2" pos="0.006000 -0.020000 -0.010000" />
                          <body name="3proxph" pos=" 0.00024 -0.02629 0.001778" quat="1.0 0.0 0.0 0.0">
                            <geom name="3proxph" type="mesh" mesh="3proxph" class="bone" />
                            <geom name="3proxph_skin_r" size="0.009 0.02" pos="0.001 -0.022 0.004" euler="1.5 0.045 -0.35" class="skin"/>
                            <geom name="Thirdpm_r" pos="0.00170 -0.04390 0.00500" euler="1.80886 -1.50604 1.85319" class="wrap" size="0.00500 0.00500" type="cylinder" />
                            <site name="EDCM_r_Thirdpm_r_sidesite" pos="0.00170 -0.04390 0.02000" />
                            <site name="FDSM-P6" pos="0.001000 -0.011000 -0.009000" />
                            <site name="FDSM-P7" pos="0.003000 -0.037000 -0.002000" />
                            <site name="FDPM-P6" pos="0.000500 -0.016000 -0.005644" />
                            <site name="FDPM-P7" pos="0.002380 -0.036430 -0.001000" />
                            <site name="EDCM-P5" pos="-0.001180 -0.012000 0.010740" />
                            <site name="EDCM-P6" pos="0.001690 -0.041390 0.011270" />
                            <site name="2ndDI-P3" pos="0.008000 -0.012000 0.000000" />
                            <site name="3rdDI-P3" pos="-0.006000 -0.014000 0.001000" />
                            <site name="LUMM-P3" pos="0.009000 -0.016000 0.005000" />
                            <site name="LUMM-P4" pos="0.008353 -0.028158 0.006986" />
                            <joint name="3mcp_abduction" type="hinge" pos="0 0 0" axis="-0.021499 0.118897 0.992674" limited="true" range="-0.261799 0.261799" ref="0"></joint>
                            <joint name="3mcp_flexion" type="hinge" pos="0 0 0" axis="0.998349 0.0473371 -0.0104129" limited="true" range="-0.785398   1.5708" ref="0"></joint>
                            <body name="3midph" pos=" 0.00165 -0.044211  0.00623" quat="1.0 0.0 0.0 0.0">
                              <geom name="3midph" type="mesh" mesh="3midph" class="bone" />
                              <geom name="3midph_skin_r" size="0.008 0.013" pos="0.0012 -0.014 0.00" euler="1.55 0.06 -0.35" class="skin"/>
                              <geom name="Thirdmd_r" pos="0.00140 -0.02800 0.00120" euler="1.37881 -1.49330 1.51861" class="wrap" size="0.00400 0.00500" type="cylinder" />
                              <site name="EDCM_r_Thirdmd_r_sidesite" pos="0.00140 -0.02800 0.01520" />
                              <site name="FDSM-P8" pos="0.000230 -0.010750 -0.005410" />
                              <site name="FDPM-P8" pos="0.001580 -0.011490 -0.005120" />
                              <site name="FDPM-P9" pos="0.002130 -0.021440 -0.002130" />
                              <site name="EDCM-P7" pos="0.000390 -0.004230 0.006250" />
                              <site name="EDCM-P8" pos="0.000948 -0.028750 0.005434" />
                              <joint name="3pm_flexion" type="hinge" pos="0 0 0" axis="0.992829 -0.062002 0.102203" limited="true" range="       0  1.74533" ref="0"></joint>
                              <body name="3distph" pos="0.001365 -0.029047 0.001954" quat="1.0 0.0 0.0 0.0">
                                <geom name="3distph" type="mesh" mesh="3distph" class="bone" />
                                <geom name="3distph_skin_r" size="0.007 0.006" pos="0.0013 -0.009 0" euler="1.55 0.05 0" class="skin"/>
                                <site name="FDPM-P10" pos="0.000060 -0.005010 -0.004190" />
                                <site name="EDCM-P9" pos="-0.000580 -0.006940 0.003080" />
                                <joint name="3md_flexion" type="hinge" pos="0 0 0" axis="0.994589 0.036103 0.097409" limited="true" range="       0  1.39626" ref="0"></joint>
                              </body>
                            </body>
                          </body>
                        </body>
                        <body name="fourthmc" pos=" -0.0097  -0.0147   0.0015" quat="1.0 0.0 0.0 0.0">
                          <geom name="4mc_new" type="mesh" mesh="4mc_new" class="bone" />
                          <geom name="fourthmc_skin_r" size="0.01 0.023" pos="-0.002 -0.024 0.004" euler="1.45 -0.1 0" class="skin"/>
                          <geom name="_4thmcp_r" pos="-0.00570 -0.05087 0.00441" euler="-2.97212 -1.22173 -2.46318" class="wrap" size="0.00500 0.01000" type="cylinder" />
                          <site name="EDCR_r__4thmcp_r_sidesite" pos="-0.00570 -0.05087 0.01941" />
                          <site name="FDPR_r__4thmcp_r_sidesite" pos="-0.00570 -0.05087 -0.01059" />
                          <site name="FDSR_r__4thmcp_r_sidesite" pos="-0.00570 -0.05087 -0.01059" />
                          <site name="FDSL-P4" pos="-0.009270 -0.017401 -0.006515" />
                          <site name="FDSR-P5" pos="-0.003000 -0.039000 -0.005000" />
                          <site name="FDPL-P4" pos="-0.010708 -0.016516 0.000413" />
                          <site name="FDPR-P5" pos="-0.003000 -0.039000 -0.001000" />
                          <site name="EDCR-P4" pos="-0.004000 -0.049000 0.013000" />
                          <site name="2ndPI-P2" pos="0.001000 -0.047000 0.002500" />
                          <site name="4thDI-P1" pos="-0.005000 -0.007000 -0.003000" />
                          <site name="4thDI-P2" pos="-0.010000 -0.042000 0.007000" />
                          <site name="LUML-P1" pos="-0.002632 -0.007801 -0.005177" />
                          <site name="LUMR-P2" pos="0.000000 -0.039000 -0.001000" />
                          <joint name="4cmc_flexion" type="hinge" pos="0 0 0" axis="    0.58  -0.8006  -0.1506" limited="true" range="       0   0.2032" ref="0"></joint>
                          <body name="4proxph" pos=" -0.0053  -0.0489    0.007" quat="1.0 0.0 0.0 0.0">
                            <geom name="4proxph_new" type="mesh" mesh="4proxph_new" class="bone" />
                            <geom name="4proxph_skin_r" size="0.009 0.016" pos="-0.002 -0.021 0.003" euler="1.48 -0.10 0" class="skin"/>
                            <geom name="Fourthpm_r" pos="-0.00416 -0.03980 0.00418" euler="0.00000 -1.50000 0.00000" class="wrap" size="0.00400 0.00500" type="cylinder" />
                            <site name="EDCR_r_Fourthpm_r_sidesite" pos="-0.00416 -0.03980 0.01818" />
                            <site name="FDSR-P6" pos="-0.002000 -0.012000 -0.006000" />
                            <site name="FDSR-P7" pos="-0.000800 -0.036000 0.002000" />
                            <site name="FDPR-P6" pos="-0.003000 -0.011000 -0.009000" />
                            <site name="FDPR-P7" pos="-0.005000 -0.033000 0.002000" />
                            <site name="EDCR-P5" pos="0.001000 -0.007000 0.009000" />
                            <site name="EDCR-P6" pos="-0.003000 -0.037000 0.009000" />
                            <site name="2ndPI-P3" pos="0.006000 -0.010000 -0.002000" />
                            <site name="4thDI-P3" pos="-0.008000 -0.012000 -0.002000" />
                            <site name="LUMR-P3" pos="0.003000 -0.012000 -0.007000" />
                            <site name="LUMR-P4" pos="0.003000 -0.017000 0.003000" />
                            <joint name="4mcp_abduction" type="hinge" pos="0 0 0" axis="-0.022094 0.144366 0.989278" limited="true" range="-0.261799 0.261799" ref="0"></joint>
                            <joint name="4mcp_flexion" type="hinge" pos="0 0 0" axis="0.994818 -0.06526 -0.029717" limited="true" range="-0.785398   1.5708" ref="0"></joint>
                            <body name="4midph" pos=" -0.0039  -0.0398   0.0057" quat="1.0 0.0 0.0 0.0">
                              <geom name="4midph_new" type="mesh" mesh="4midph_new" class="bone" />
                              <geom name="4midph_skin_r" size="0.008 0.011" pos="-0.001 -0.012 0.0015" euler="1.48 -0.08 0" class="skin"/>
                              <geom name="Fourthmd_r" pos="-0.00264 -0.02300 0.00256" euler="0.00000 -1.50000 0.00000" class="wrap" size="0.00500 0.00500" type="cylinder" />
                              <site name="EDCR_r_Fourthmd_r_sidesite" pos="-0.00264 -0.02300 0.01756" />
                              <site name="FDSR-P8" pos="-0.000900 -0.012000 -0.000700" />
                              <site name="FDPR-P8" pos="-0.000220 -0.007589 -0.005868" />
                              <site name="FDPR-P9" pos="-0.001647 -0.019679 0.000548" />
                              <site name="EDCR-P7" pos="0.001263 -0.005000 0.007000" />
                              <site name="EDCR-P8" pos="-0.000193 -0.023000 0.007000" />
                              <joint name="4pm_flexion" type="hinge" pos="0 0 0" axis="0.995828 -0.0345807 0.0923249" limited="true" range="       0  1.74533" ref="0"></joint>
                              <body name="4distph" pos=" -0.0026  -0.0245   0.0033" quat="1.0 0.0 0.0 0.0">
                                <geom name="4distph_new" type="mesh" mesh="4distph_new" class="bone" />
                                <geom name="4distph_skin_r" size="0.007 0.006" pos="0 -0.01 0" euler="1.4 -0.1 0" class="skin"/>
                                <site name="FDPR-P10" pos="-0.000913 -0.003901 -0.003112" />
                                <site name="EDCR-P9" pos="0.001539 -0.004000 0.005000" />
                                <joint name="4md_flexion" type="hinge" pos="0 0 0" axis="  0.9526    -0.14   0.2701" limited="true" range="       0  1.39626" ref="0"></joint>
                              </body>
                            </body>
                          </body>
                        </body>
                        <body name="fifthmc" pos=" -0.0171  -0.0118  -0.0036" quat="1.0 0.0 0.0 0.0">
                          <geom name="5mc_new" type="mesh" mesh="5mc_new" class="bone" />
                          <geom name="fifthmc_skin_1_r" size="0.01 0.022" pos="-0.006 -0.02 0.005" euler="1.35 -0.25 0" class="skin"/>
                          <geom name="_5thmcp_r" pos="-0.01300 -0.04300 0.01002" euler="-2.67175 -1.50000 -2.46598" class="wrap" size="0.00500 0.01000" type="cylinder" />
                          <site name="FDM_r__5thmcp_r_sidesite" pos="-0.01300 -0.04300 -0.00498" />
                          <site name="ADM_r__5thmcp_r_sidesite" pos="-0.01300 -0.04300 -0.00498" />
                          <site name="EDM_r__5thmcp_r_sidesite" pos="-0.01300 -0.04300 0.02502" />
                          <site name="EDCL_r__5thmcp_r_sidesite" pos="-0.01300 -0.04300 0.02502" />
                          <site name="FDPL_r__5thmcp_r_sidesite" pos="-0.01300 -0.04300 -0.00498" />
                          <site name="FDSL_r__5thmcp_r_sidesite" pos="-0.01300 -0.04300 -0.00498" />
                          <site name="FDSL-P5" pos="-0.010000 -0.034000 0.001442" />
                          <site name="FDPL-P5" pos="-0.011000 -0.036000 0.004000" />
                          <site name="EDCL-P4" pos="-0.009800 -0.039300 0.015700" />
                          <site name="EDM-P5" pos="0.001979 0.002464 0.007758" />
                          <site name="EDM-P6" pos="-0.011042 -0.038531 0.015012" />
                          <site name="ADM-P2" pos="-0.015383 -0.036418 -0.001729" />
                          <site name="FDM-P2" pos="-0.018229 -0.035911 0.004213" />
                          <site name="ODM-P2" pos="-0.007930 -0.028290 0.003228" />
                          <site name="3rdPI-P1" pos="-0.000000 -0.012000 0.003000" />
                          <site name="3rdPI-P2" pos="-0.004500 -0.042500 0.007000" />
                          <site name="LUML-P2" pos="-0.005000 -0.038000 0.001000" />
                          <joint name="CMC5_r1" type="hinge" pos="0 0 0" axis="  0.3718  -0.8665   0.3333" limited="true" range="-1 1" ref="0"></joint>
                          <body name="5proxph" pos=" -0.0111  -0.0423   0.0097" quat="1.0 0.0 0.0 0.0">
                            <geom name="5proxph_new" type="mesh" mesh="5proxph_new" class="bone" />
                            <geom name="5proxph_skin_r" size="0.009 0.012" pos="-0.008 -0.020 0.003" euler="1.5 -0.3 0" class="skin"/>
                            <geom name="Fifthpm_r" pos="-0.01332 -0.03272 0.00294" euler="-1.75000 -1.10000 -2.95449" class="wrap" size="0.00400 0.00500" type="cylinder" />
                            <site name="EDM_r_Fifthpm_r_sidesite" pos="-0.01332 -0.03272 0.01694" />
                            <site name="EDCL_r_Fifthpm_r_sidesite" pos="-0.01332 -0.03272 0.01694" />
                            <site name="FDSL-P6" pos="-0.005000 -0.014000 -0.004000" />
                            <site name="FDSL-P7" pos="-0.010820 -0.024244 -0.000000" />
                            <site name="FDPL-P6" pos="-0.004000 -0.010000 -0.004000" />
                            <site name="FDPL-P7" pos="-0.011878 -0.028000 -0.003000" />
                            <site name="EDCL-P5" pos="-0.001386 -0.006000 0.008641" />
                            <site name="EDCL-P6" pos="-0.010492 -0.030000 0.009867" />
                            <site name="EDM-P7" pos="-0.001386 -0.006000 0.008641" />
                            <site name="EDM-P8" pos="-0.010492 -0.030022 0.009867" />
                            <site name="ADM-P3" pos="-0.011500 -0.010000 -0.002000" />
                            <site name="FDM-P3" pos="-0.011500 -0.010000 -0.002000" />
                            <site name="3rdPI-P3" pos="0.003000 -0.015000 -0.002000" />
                            <site name="LUML-P3" pos="-0.001500 -0.019000 -0.003000" />
                            <site name="LUML-P4" pos="-0.003020 -0.022000 0.004000" />
                            <joint name="5mcp_abduction" type="hinge" pos="0 0 0" axis="-0.025001 0.216206 0.976028" limited="true" range="-0.261799 0.261799" ref="0"></joint>
                            <joint name="5mcp_flexion" type="hinge" pos="0 0 0" axis="0.971501 -0.212817 -0.0344635" limited="true" range="-0.785398   1.5708" ref="0"></joint>
                            <body name="5midph" pos=" -0.0125  -0.0335   0.0043" quat="1.0 0.0 0.0 0.0">
                              <geom name="5midph_new" type="mesh" mesh="5midph_new" class="bone" />
                              <geom name="5midph_skin_r" size="0.008 0.006" pos="-0.004 -0.012 0" euler="1.5 -0.3 0" class="skin"/>
                              <geom name="Fifthmd_r" pos="-0.00737 -0.01941 0.00136" euler="-2.00000 -1.25000 -1.75000" class="wrap" size="0.00500 0.00500" type="cylinder" />
                              <site name="EDM_r_Fifthmd_r_sidesite" pos="-0.00737 -0.01941 0.01636" />
                              <site name="EDCL_r_Fifthmd_r_sidesite" pos="-0.00737 -0.01941 0.01636" />
                              <site name="FDSL-P8" pos="-0.004197 -0.005272 -0.006143" />
                              <site name="FDPL-P8" pos="-0.006111 -0.007732 -0.005641" />
                              <site name="FDPL-P9" pos="-0.007034 -0.015120 -0.001723" />
                              <site name="EDCL-P7" pos="-0.000199 -0.007038 0.005787" />
                              <site name="EDCL-P8" pos="-0.004634 -0.019063 0.005019" />
                              <site name="EDM-P9" pos="-0.000199 -0.007038 0.005787" />
                              <site name="EDM-P10" pos="-0.005359 -0.019927 0.005896" />
                              <joint name="5pm_flexion" type="hinge" pos="0 0 0" axis=" 0.92871 -0.327713 0.176591" limited="true" range="       0  1.74533" ref="0"></joint>
                              <body name="5distph" pos=" -0.0075  -0.0195    0.002" quat="1.0 0.0 0.0 0.0">
                                <geom name="5distph_new" type="mesh" mesh="5distph_new" class="bone" />
                                <geom name="5distph_skin_r" size="0.007 0.006" pos="-0.003 -0.009 0" euler="1.5 -0.3 0" class="skin"/>
                                <site name="FDPL-P10" pos="-0.005206 -0.010796 -0.002787" />
                                <site name="EDCL-P9" pos="-0.001802 -0.006843 0.004364" />
                                <site name="EDM-P11" pos="-0.000570 -0.007148 0.004225" />
                                <joint name="5md_flexion" type="hinge" pos="0 0 0" axis="0.892729 -0.426766 0.144588" limited="true" range="       0  1.39626" ref="0"></joint>
                              </body>
                            </body>
                          </body>
                        </body>
                      </body>
                    </body>
                  </body>
                </body>
                <site name="LD_L1_r-P1" pos="-0.009487 -0.015253 0.002689" />
                <site name="LD_L2_r-P1" pos="-0.009490 -0.015250 0.002690" />
                <site name="LD_L3_r-P1" pos="-0.009490 -0.015250 0.004330" />
                <site name="LD_L4_r-P1" pos="-0.009490 -0.015250 0.002690" />
                <site name="LD_L5_r-P1" pos="-0.009490 -0.015250 0.002690" />
                <site name="LD_T12_r-P1" pos="-0.009490 -0.015250 0.002690" />
                <site name="LD_T11_r-P1" pos="-0.009490 -0.015250 0.002690" />
                <site name="LD_T10_r-P1" pos="-0.009490 -0.015250 0.002690" />
                <site name="LD_T9_r-P1" pos="-0.009490 -0.015250 0.002690" />
                <site name="LD_T8_r-P1" pos="-0.009490 -0.015250 0.002690" />
                <site name="LD_T7_r-P1" pos="-0.009490 -0.015250 0.002690" />
                <site name="LD_R12_r-P1" pos="-0.009490 -0.015250 0.002690" />
                <site name="LD_R11_r-P1" pos="-0.009490 -0.015250 0.004330" />
                <site name="LD_IL_r-P1" pos="-0.009490 -0.015250 0.002690" />
              </body>
            </body>
          </body>
        </body>
        <site name="trap_acr_scap-P1" pos="-0.037297 0.000000 -0.023654" />
        <site name="trap_acr_T1-P1" pos="-0.037297 0.000000 -0.023654" />
        <site name="trap_acr_T1-P2" pos="-0.082345 0.015000 -0.128007" />
        <site name="trap_acr_T2-P1" pos="-0.037297 0.000000 -0.023654" />
        <site name="trap_acr_T2-P2" pos="-0.096895 0.013000 -0.138249" />
        <site name="trap_acr_T3-P1" pos="-0.037297 0.000000 -0.023654" />
        <site name="trap_acr_T3-P2" pos="-0.100500 0.002000 -0.143386" />
        <site name="trap_inf_T4-P2" pos="-0.100584 -0.019000 -0.131472" />
        <site name="trap_inf_T4-P3" pos="-0.088507 -0.006000 -0.076654" />
        <site name="trap_inf_T5-P2" pos="-0.105902 -0.028000 -0.135714" />
        <site name="trap_inf_T5-P3" pos="-0.088507 -0.006000 -0.076654" />
        <site name="trap_inf_T6-P2" pos="-0.106681 -0.040000 -0.133214" />
        <site name="trap_inf_T6-P3" pos="-0.088507 -0.006000 -0.076654" />
        <site name="trap_inf_T7-P2" pos="-0.110013 -0.052000 -0.127368" />
        <site name="trap_inf_T7-P3" pos="-0.088507 -0.006000 -0.076654" />
        <site name="trap_inf_T8-P2" pos="-0.113826 -0.070000 -0.123250" />
        <site name="trap_inf_T8-P3" pos="-0.088507 -0.006000 -0.076654" />
        <site name="trap_inf_T9-P2" pos="-0.118963 -0.087000 -0.121467" />
        <site name="trap_inf_T9-P3" pos="-0.088507 -0.006000 -0.076654" />
        <site name="trap_inf_T10-P3" pos="-0.118417 -0.100000 -0.119344" />
        <site name="trap_inf_T10-P4" pos="-0.088507 -0.006000 -0.076654" />
        <site name="trap_inf_T11-P4" pos="-0.117963 -0.112000 -0.116120" />
        <site name="trap_inf_T11-P5" pos="-0.088507 -0.006000 -0.076654" />
        <site name="trap_inf_T12-P5" pos="-0.117725 -0.120000 -0.110244" />
        <site name="trap_inf_T12-P6" pos="-0.088507 -0.006000 -0.076654" />
      </body>
    </body>
    <site name="trap_cl-P1" pos="-0.047788 0.023200 0.075871" />
  </body>
</mujoco>